Can an inner catch rethrow an exception to an outer catch?

Yes.
