What is wrong with this fragment?
```java
// ...
vals[18] = 10;
catch (ArrayIndexOutOfBoundsException exc) {
	// Handling of error.
}
```
The assignment of the array before the catch block is not placed inside a try block. 
